

[TOC]



# 一、协程的异常处理方式

------

协程的异常处理方式一共有如下三种方式：

1. 通过 try-catch 捕获异常

2. 通过 CoroutineExceptionHandler 捕获异常

3. 全局异常处理（服务注册）

下面就详细介绍一下这三种方式。

## 1、通过 try-catch 捕获异常

在开发中，对于可能产生异常的代码，通常的做法都是使用try-catch包裹住可能发生异常的代码。

### 1-1、try-catch 正常捕获异常

以一个普通的请求为例：

```kotlin
fun main() = runBlocking<Unit> {
    val scope = CoroutineScope(Job())
    scope.launch {
        val num = doHardWork()
        println("计算结果：num=$num")
    }
    delay(2000)
}

// 模拟耗时操作
private suspend fun doHardWork(): Int {
    delay(500) // 模拟耗时操作
    return try {
        1 / 0
    } catch (e: Exception) {
        println("try catch exception:$e")
        -1
    }
}
```

允许结果：

> try catch exception:java.lang.ArithmeticException: / by zero
> 计算结果：num=-1
>
> Process finished with exit code 0

从结果上看，能够正常的答应异常信息和结果，说明try catch 有捕获异常。

上述为一般状况下处理协程异常的方法，但是在某些情况下，try-catch却也存在捕获不到异常的可能。



### 1-2、通过 try-catch 失效

正常来说，try-catch块中只有代码块存在异常，都将被捕获到catch中。但是协程中的异常却存在特殊情况。

异常是否能够正确的被捕获，关键要看try catch 加在什么地方，如下面这种情况，try catch 就失效了：

```kotlin
fun main() = runBlocking<Unit> {
    val scope = CoroutineScope(Job())
    scope.launch {
        try {// try-catch 加在了 协程的外面
            launch {
                val num = doHardWork()
                println("计算结果：num=$num")
            }
        } catch (e: Exception) {
            println("try catch exception:$e")
        }
    }
    delay(2000)
}

private suspend fun doHardWork(): Int {
    delay(500) // 模拟耗时操作
    return 1 / 0
}
```

运行结果，直接奔溃，并在控制台上输出了异常打印：

> Exception in thread "DefaultDispatcher-worker-2" java.lang.ArithmeticException: / by zero

在这个demo 中，用 try  catch 把协程给包裹住了，从运行的结果可以看出，程序直接奔溃了，说明异常没有被捕获。

为什么 try- catch 会失效呢？

其实想想也能够理解，launch 是启动一个协程。就像在Java 中，启动一个线程一样，我们无法通过try catch 去包裹 启动线程的 start 方法，从而捕获线程的异常，只能在线程执行体中去捕获具体的异常。

线程，通过 start 方法，运行一个线程，只是把线程对象的状态修改为 可执行状态，并等待cpu的调度，并不会立即执行。

协程，通过launch方法，创建一个协程并运行，跟线程一样，协程也不是立即就执行的，也是需要等待CPU的调度才会执行。



## 2、通过 CoroutineExceptionHandler 捕获异常

try  catch 捕获异常的缺点就是：

* try catch 在协程中可能失效
* 可能存在未被 try catch 的情况而产生异常

不知道什么时候就会产生异常，而异常又没有被捕获的话，程序就会奔溃。这就导致协程的**安全性降低**了。

协程可以通过  CoroutineExceptionHandler 来处理异常。

### 2-1、CoroutineExceptionHandler

官方给的定义：

> 将**未捕获**异常打印到控制台的默认行为是可自定义的。 *根*协程中的 [CoroutineExceptionHandler](https://link.juejin.cn?target=https%3A%2F%2Fkotlin.github.io%2Fkotlinx.coroutines%2Fkotlinx-coroutines-core%2Fkotlinx.coroutines%2F-coroutine-exception-handler%2Findex.html) 上下文元素可以被用于这个根协程通用的 `catch` 块，及其所有可能自定义了异常处理的子协程。 它类似于 `Thread.uncaughtExceptionHandler`) 。 你无法从 `CoroutineExceptionHandler` 的异常中恢复。当调用处理者的时候，协程已经完成并带有相应的异常。通常，该处理者用于记录异常，显示某种错误消息，终止和（或）重新启动应用程序。

从上面的描述可以知道：

* （1）CoroutineExceptionHandler 需要设置在根协程上才有效
* （2）CoroutineExceptionHandler 可以用于处理未被捕获的异常，即CoroutineExceptionHandler 是协程处理异常的最后保障。
* （3）当进入到 CoroutineExceptionHandler 中，说明协程已经被销毁了，且该写出无法恢复。

### 2-2、实践

下面通过一个实例来演示一下，如下所示：

```kotlin
fun main() {
    val handler = CoroutineExceptionHandler { _, throwable ->
        println("handler 捕获异常：$throwable")
    }
    val scope = CoroutineScope(Job())
    scope.launch(handler) {// 根协程
        launch {// 子协程
            println("开始执行耗时操作")
            val num = doHardWork()
            println("num=$num")
        }
    }
    Thread.sleep(2000)
}

private suspend fun doHardWork(): Int {
    delay(500) // 模拟耗时操作
    return 1 / 0
}
```

运行的结果：

> 开始执行耗时操作
> handler 捕获异常：java.lang.ArithmeticException: / by zero

从打印的信息来看，未被捕获的异常，确实是被 CoroutineExceptionHandler 对象所捕获 了，而且程序也没有奔溃。

为什么在子协程中产生的异常，会被根协程的 CoroutineExceptionHandler 所捕获呢？继续看下面的：**第二节：协程异常上报的原理**

### 2-3、不足之处

可见CoroutineExceptionHandler处理了我们的异常，但是它也有一些不足之处：

1. 首先根据协程的结构化并发特性，子协程未捕获的异常会向上传递，父协程会失败，并且取消所有的子协程。
2. 根据它的定义，他是一种全局的处理机制，不能处理局部异常。
3. 它只能在顶级协程中生效。

所以如果你想并行执行多个操作，并且之间互相不影响，这时CoroutineExceptionHandler就显得不合适了，使用SupervisorJob，supervisorScope就可以解决上面的问题。



## 3、全局异常处理（服务注册）

在调用协程的时候，通过传入一个 CoroutineExceptionHandler 可以处理当前协程的 未捕获异常，那如果忘记传 CoroutineExceptionHandler 了，导致程序奔溃了，如果这个奔溃是在线上的，这不就没办法定位异常了吗？

这个时候就需要给我们的程序设置一个全局的异常处理类，用于全局捕获程序中 未捕获的异常。这就跟 Java 中捕获全局异常类似，如在Java中，通过设置全局的 Thread.UncaughtExceptionHandler 对象，来处理全局异常：

```java
Thread.setDefaultUncaughtExceptionHandler(new Thread.UncaughtExceptionHandler() {
    @Override
    public void uncaughtException(@NonNull Thread t, @NonNull Throwable e) {


    }
});
```

协程也可以设置一个全局的 CoroutineExceptionHandler 来处理全局异常。

### 3-1 、定义一个处理全局未捕获异常的 CoroutineExceptionHandler 类

```kotlin
@Keep
class GlobalCoroutineExceptionHandler : CoroutineExceptionHandler {
    override val key: CoroutineContext.Key<*> = CoroutineExceptionHandler

    @SuppressLint("LongLogTag")
    override fun handleException(context: CoroutineContext, exception: Throwable) {
      	// todo 可以把这个异常上报，方便定位线上bug
        Log.w("GlobalCoroutineExceptionHandler", "context=${context} ")
        exception.printStackTrace()
    }
}
```

###  3-2、注册服务到 ServiceLoader 

注册CoroutineExceptionHandler 对象到 ServiceLoader 有两种方式：

* （1）手动注册
* （2）通过谷歌提供的插件，自动注册：[谷歌动态注册服务插件](https://github.com/google/auto/tree/master/service)

这里就介绍收到注册的方式。以Android工程为例，具体步骤如下：

* （1）在 main 目录下，创建 resources 目录。

* （2）在 resources 目录下，创建 META-INF 目录

* （3）在 META-INF 目录下，创建 services 目录

* （4）**在 services 目录下，创建 kotlinx.coroutines.CoroutineExceptionHandler 文件，注意这里的文件名，是 CoroutineExceptionHandler 类的全类名。表示该服务实现的接口。**

* （4）文件内容，填入自己写的全局异常处理类的全类名，如：

   com.mei.kotlinexception.globalhandler.GlobalCoroutineExceptionHandler

这样就完成了 CoroutineExceptionHandler 服务的注册。

当协程没有指定 CoroutineExceptionHandler 异常处理对象的时候，异常的处理最终会走到 我们定义的这个 全局异常处理类：GlobalCoroutineExceptionHandler。

这样即使发生线上的奔溃，我们也能够搜集异常，并定位异常了。

协程捕获异常的顺序：

* 有点使用协程自己设置的 CoroutineExceptionHandler
* 如果协程没有设置，则使用全局的 CoroutineExceptionHandler，
* 如果没有设置全局的 CoroutineExceptionHandler，则使用线程的 UncaughtExceptionHandler 。

源码如下：

```kotlin
public fun handleCoroutineException(context: CoroutineContext, exception: Throwable) {
    // Invoke an exception handler from the context if present
    try {
      // 1. 获取协程设置的 CoroutineExceptionHandler 处理异常
        context[CoroutineExceptionHandler]?.let {
            it.handleException(context, exception)
            return
        }
    } catch (t: Throwable) {
        handleCoroutineExceptionImpl(context, handlerException(exception, t))
        return
    }
    // If a handler is not present in the context or an exception was thrown, fallback to the global handler
    handleCoroutineExceptionImpl(context, exception)
}

internal actual fun handleCoroutineExceptionImpl(context: CoroutineContext, exception: Throwable) {
    // use additional extension handlers
  // 2. 使用全局的CoroutineExceptionHandler 处理异常
    for (handler in handlers) {
        try {
            handler.handleException(context, exception)
        } catch (t: Throwable) {
            // Use thread's handler if custom handler failed to handle exception
            val currentThread = Thread.currentThread()
            currentThread.uncaughtExceptionHandler.uncaughtException(currentThread, handlerException(exception, t))
        }
    }

    // use thread's handler
  // 3. 使用 线程设置的 UncaughtExceptionHandler 对象处理异常
    val currentThread = Thread.currentThread()
    currentThread.uncaughtExceptionHandler.uncaughtException(currentThread, exception)
}
```

# 二、协程异常处理流程

------

在讲解异常处理流程之前，先来看一个demo：

```kotlin
fun main() = runBlocking {
    val handler = CoroutineExceptionHandler { _, throwable ->
        println("handler 捕获异常：$throwable")
    }
    val scope = CoroutineScope(Job())
    scope.launch {
        launch(handler) {// handler 放在了子协程上
            println("开始执行耗时操作")
            throw NullPointerException()
        }
    }.join()
}
```

在这里例子中，把异常处理对象传给了子协程，这样还能正常的捕获异常吗？

运行之后，程序奔溃了，结果如下：

![image-20220811093438009](https://raw.githubusercontent.com/meiSThub/BlogImage/master/2022image-20220811093438009.png)

CoroutineExceptionHandler 并没有捕获到异常。这是为什么呢，难道CoroutineExceptionHandler只能设置在根协程才有效果吗？

**疑问**：CoroutineExceptionHandler 是不是只设置给根协程才有效果？

## 1、Job树

当在一个协程中，启动另一个协程时，新协程的Job对象会和原来的协程Job组成父子关系，并建立一颗Job树。启动的子协程越多，job 树节点也越多。而且在子协程中，还可以启动新的子协程。

如下面的代码：

```kotlin
fun main() = runBlocking {
    val jobRoot = Job()
    val scope = CoroutineScope(jobRoot)
    scope.launch {
        println("job1")
    }.join()
    scope.launch {
        println("job2")
        launch {
            println("job4")
        }
        launch {
            println("job5")
        }
    }.join()
    scope.launch {
        println("job3")
    }.join()
}
```

这个程序中，Job组成的Job树就如下图所示：

![image-20220811095520466](https://raw.githubusercontent.com/meiSThub/BlogImage/master/2022image-20220811095520466.png)

画成树形结构，就如下图所示：

![image-20220811094720152](https://raw.githubusercontent.com/meiSThub/BlogImage/master/2022image-20220811094720152.png)

其中jobRoot就是根，job1，job2和job3 就是jobRoot的子节点，job4和job5是 jobRoot的孙子节点。

具体在代码中是如何去构建这颗树的，大家可以去看 启动协程的源码（launch方法）。

## 2、Job和SupervisorJob

当一个协程发生了异常之后，异常就会在Job树上进行传播。而根据Job类型的不同，处理异常的方式也会不一样。这种差异就体现在： Job 和 SupervisorJob 上。

而 Job 和 SupervisorJob 的一个区别是：**Job的子协程发生异常被取消会同时取消Job的其它子协程，而SupervisorJob不会**。

正是因为 Job 和 SupervisorJob 对异常处理的差异，导致了 CoroutineExceptionHandler 处理异常的不确定性：

* 什么时候能处理异常
* 什么时候不能处理异常。

### 2-1、通过案例了解 Job 和 SuperVisorJob 的区别

 Job 和 SupervisorJob 的区别，可以通过下面的例子验证：

（1）Job启动了3个子协程job1、job2、job3。job1 delay 100毫秒后发生异常，协程被取消了，job2和job3也同样被取消了。

```kotlin
private suspend fun testJob() {
    val handler = CoroutineExceptionHandler { coroutineContext, throwable ->
        println("caught exception in handler $throwable ")
    }
    val scope = CoroutineScope(Job() + handler)
    scope.launch {
        delay(100)
        println("job1,抛异常")
        throw NullPointerException()
    }.join()
    scope.launch {
        delay(200)
        println("job2")
    }.join()
    scope.launch {
        delay(300)
        println("job3")
    }.join()
}
```

运行结果如下：

![image-20220811101426379](https://raw.githubusercontent.com/meiSThub/BlogImage/master/2022image-20220811101426379.png)

（1）SupervisorJob启动了3个子协程job1、job2、job3。job1 delay 100毫秒后发生异常，协程被取消了，job2和job3并不受影响。

```kotlin
private suspend fun testSupervisorJob(){
    val handler = CoroutineExceptionHandler { coroutineContext, throwable ->
        println("caught exception in handler $throwable ")
    }
    val scope = CoroutineScope(SupervisorJob() + handler)
    scope.launch {
        delay(100)
        println("job1,抛异常")
        throw NullPointerException()
    }.join()
    scope.launch {
        delay(200)
        println("job2")
    }.join()
    scope.launch {
        delay(300)
        println("job3")
    }.join()
}
```

这个方法跟 testJob() 方法，唯一的区别就是在创建 CoroutineScope 对象的时候，把 Job 对象，换成了 SupervisorJob 对象，其它都一样，但运行的结果却千差万别。

![image-20220811101835199](https://raw.githubusercontent.com/meiSThub/BlogImage/master/2022image-20220811101835199.png)

异常被捕获了，job2 和 job3 也正常运行直到结束，并没有受到 job1 异常的影响。

下面就通过源码，去了解一下造成这种差异的原因。

### 2-2、通过源码了解 Job 和 SupervisorJob 的区别

首先看下 Job 和 SupervisorJob 的创建：

```kotlin
// 1. Job对象的创建
public fun Job(parent: Job? = null): CompletableJob = JobImpl(parent)
// 2. SupervisorJob 对象的创建
public fun SupervisorJob(parent: Job? = null) : CompletableJob = SupervisorJobImpl(parent)
// 3. SupervisorJobImpl 类继承与 JobImpl 类
private class SupervisorJobImpl(parent: Job?) : JobImpl(parent) {
    override fun childCancelled(cause: Throwable): Boolean = false
}
```

从上面可以看出，Job()返回的是JobImpl对象，SupervisorJob()返回的SupervisorJobImpl对象。而SupervisorJobImpl是JobImpl的子类，并且重写了childCancelled方法，返回值为false。JobImpl继承自JobSupport，它的childCancelled方法源码如下：

```kotlin
public open fun childCancelled(cause: Throwable): Boolean {
    if (cause is CancellationException) return true
    return cancelImpl(cause) && handlesException
}
```

当协程被取消时，会调用父Job的childCancelled方法。SupervisorJobImpl直接返回false，表示父Job不会因为子Job被取消而跟随取消。而JobSupport会调用cancelImpl方法，该方法的作用是取消父Job和父Job的所有子Job。

注意：Job 和 SupervisorJob 唯一的区别就是，SupervisorJob 重写了 **childCancelled** 方法，直接返回了 **false**。

下面就看看这个方法 对异常处理 到底有什么影响。

## 3、异常的传播流程

在协程发生异常的时候，最终会调用到 JobSupport 的 finalizeFinishingState 方法：

```kotlin
private fun finalizeFinishingState(state: Finishing, proposedUpdate: Any?): Any? {
    ....
    // Now handle the final exception,处理最终异常
    if (finalException != null) {
      // 1.cancelParent 是否取消父Job
      // 2.handleJobException 当前Job自己处理异常
        val handled = cancelParent(finalException) || handleJobException(finalException)
        if (handled) (finalState as CompletedExceptionally).makeHandled()
    }
    .... 
    return finalState
}
```

只看关键代码，finalizeFinishingState 中主要就做了两件事：

* （1）调用 cancelParent 方法，判断是否需要取消父Job，并处理异常。
* （2）如果父Job 不处理异常，则调用 handleJobException 方法，自己处理异常。
* （3）cancelParent 返回false，则当前Job处理异常；cancelParent 返回true，则父Job处理异常。

### 3-1、cancelParent 方法

```kotlin
private fun cancelParent(cause: Throwable): Boolean {
    // Is scoped coroutine -- don't propagate, will be rethrown
    if (isScopedCoroutine) return true

    /* CancellationException 被认为是“正常的”，当孩子产生它时，父母通常不会被取消。这允许父级取消其子级（通常）而不会自行取			* 消，除非子级在完成期间崩溃并产生其他异常
     */
    val isCancellation = cause is CancellationException
    val parent = parentHandle
    // 当父Job 为空，或者 父Job 是 NonDisposableHandle 类型，则直接返回 isCancellation
  	// 如果不是 CancellationException异常，则 isCancellation 为 false
    if (parent === null || parent === NonDisposableHandle) {
        return isCancellation
    }

    // 调用 父Job 的 childCancelled 方法
    return parent.childCancelled(cause) || isCancellation
}
```

#### （1）如果父Job 是 Job 类型

则 childCancelled 方法会调用到 JobSupport 中的 childCancelled方法：

```kotlin
internal open val handlesException: Boolean get() = true

public open fun childCancelled(cause: Throwable): Boolean {
    if (cause is CancellationException) return true
  // cancelImpl 就是取消父Job并处理异常
    return cancelImpl(cause) && handlesException
}
```

handlesException 属性在 子类 JobImpl 中有重写：

```kotlin
internal open class JobImpl(parent: Job?) : JobSupport(true), CompletableJob {
    init { initParentJobInternal(parent) }
    override val onCancelComplete get() = true
    /*
     * 检查父Job是否能够处理异常
     */
    override val handlesException: Boolean = handlesException()

    @JsName("handlesExceptionF")
    private fun handlesException(): Boolean {
      // 如果当前Job没有父Job，则直接返回false
        var parentJob = (parentHandle as? ChildHandleNode)?.job ?: return false
        while (true) {
          // 如果当前Job有父Job，则调用父Job handlesException属性，如果该属性返回true，则直接返回true
            if (parentJob.handlesException) return true
          // 如果当前Job的父Job没有父Job，则直接返回false
            parentJob = (parentJob.parentHandle as? ChildHandleNode)?.job ?: return false
        }
    }
}
```

通过上面的代码可以得出如下结论：

* （1）如果Job是根节点，则childCancelled直接返回false，则表示由当前Job处理异常
* （2）如果Job不是根节点，则会把异常向上抛，交给父Job进行处理
* （3）如果节点是Job类型，且不是根节点 则 childCancelled 返回true，如果是根节点 则 childCancelled 返回false。

#### （2）如果父Job是 SupervisorJob

```kotlin
private class SupervisorJobImpl(parent: Job?) : JobImpl(parent) {
    override fun childCancelled(cause: Throwable): Boolean = false
}
```

如果父Job 是 SupervisorJob，则 childCancelled 方法一直返回false，所以 会有当前Job自己处理异常。



### 3-2、处理异常

当 Job 的 childCancelled 方法返回false 的时候，就需要当前Job自己处理异常。childCancelled 方法返回 false 的场景有：

* （1）当前 Job的父节点 是根节点
* （2）当前Job的父节点是 SupervisorJob。

在这两种场景下，就会由 当前 Job 处理异常。

JobSupport的 handleJobException 方法：

```
protected open fun handleJobException(exception: Throwable): Boolean = false
```

这里就是一个空实现，默认返回false，表示是没有处理异常。

该方法在 StandaloneCoroutine 类有重新，StandaloneCoroutine 类继承与 AbstractCoroutine 类，AbstractCoroutine 类继承与 JobSupport类。源码如下：

```kotlin
private open class StandaloneCoroutine(
    parentContext: CoroutineContext,
    active: Boolean
) : AbstractCoroutine<Unit>(parentContext, active) {
    override fun handleJobException(exception: Throwable): Boolean {
      // 具体处理异常的方法
        handleCoroutineException(context, exception)
        return true // 处理异常
    }
}
```

handleCoroutineException 方法：

```kotlin
public fun handleCoroutineException(context: CoroutineContext, exception: Throwable) {
    // Invoke an exception handler from the context if present
    try {
      // 获取当前协程上下文中设置的 CoroutineExceptionHandler 对象，并调用 handleException方法处理异常
        context[CoroutineExceptionHandler]?.let {
            it.handleException(context, exception)
            return
        }
    } catch (t: Throwable) {
        handleCoroutineExceptionImpl(context, handlerException(exception, t))
        return
    }
    // 如果当前协程上下文中没有设置 CoroutineExceptionHandler 对象，则 调用 次方法处理异常
    handleCoroutineExceptionImpl(context, exception)
}
```

handleCoroutineExceptionImpl 方法：

```kotlin
// 通过ServiceLoader去加载当前应用中，所有实现了 CoroutineExceptionHandler 接口的类，并创建对象
private val handlers: List<CoroutineExceptionHandler> = ServiceLoader.load(
        CoroutineExceptionHandler::class.java,
        CoroutineExceptionHandler::class.java.classLoader
).iterator().asSequence().toList()

// 处理异常
internal actual fun handleCoroutineExceptionImpl(context: CoroutineContext, exception: Throwable) {
    // 1.使用全局设置的异常处理类，来处理异常，可以有多个
    for (handler in handlers) {
        try {
            handler.handleException(context, exception)
        } catch (t: Throwable) {
            // Use thread's handler if custom handler failed to handle exception
            val currentThread = Thread.currentThread()
            currentThread.uncaughtExceptionHandler.uncaughtException(currentThread, handlerException(exception, t))
        }
    }

    // 2. 如果没有设置全局的异常处理类，则会调用 当前线程的 异常处理对象，处理异常
    val currentThread = Thread.currentThread()
    currentThread.uncaughtExceptionHandler.uncaughtException(currentThread, exception)
}
```

通过上面的源码分析可以知道，异常在当前Job中的处理流程如下：

* （1）优先使用当前协程设置的 CoroutineExceptionHandler 对象处理异常。
* （2）使用全局的 CoroutineExceptionHandler 对象处理异常。
* （3）使用线程的 UncaughtExceptionHandler 对象处理异常。

在 Android 开发中，使用协程的时候，都会引入 kotlinx-coroutines-android 库，如：

```groovy
implementation 'org.jetbrains.kotlinx:kotlinx-coroutines-android:1.4.3'
```

在这个库中，就为Android工程提供了默认的全局异常处理类：[AndroidExceptionPreHandler.kt](https://github.com/Kotlin/kotlinx.coroutines/blob/master/ui/kotlinx-coroutines-android/src/AndroidExceptionPreHandler.kt)。所以在Android中，当协程发生异常的时候，可以把异常打印到控制台上。

**注意：**

开发中，如果对协程的异常，是否能被你设置的 CoroutineExceptionHandler 所处理 而疑惑的时候，就可以把 Job树画出来，就能明白了。

![Kotlin协程](https://raw.githubusercontent.com/meiSThub/BlogImage/master/20222022Kotlin%E5%8D%8F%E7%A8%8B.jpg)



## 4、async协程异常

参考：[kotlin协程async await的异常踩坑以及异常处理的正确姿势](https://blog.csdn.net/yuzhiqiang_1993/article/details/121049744)

通过 **async构建器** 启动的协程，异常抛出的时机：

* （1）如果是根协程，则异常在调用 await 方法的时候才抛出，可以用try catch 进行捕获，哪怕给async设置了CoroutineExceptionHandler 对象，也是try catch 优先捕获异常。
* （2）如果是子协程，则在协程执行的时候，立即抛出，并在Job树上进行传递，直到有Job可以处理该异常。

async 跟协程：

```kotlin
fun main() = runBlocking<Unit> {
    val scope = CoroutineScope(EmptyCoroutineContext)
    val result = scope.async {
        println("Throwing exception from async")
        throw AssertionError("test")
    }
    try {
        result.await()
    } catch (e: Throwable) {
        println("try catch 异常:$e")
    }
}
// 运行结果
// Throwing exception from async
// try catch 异常:java.lang.NullPointerException: test
```

async子协程：

```kotlin
fun main() = runBlocking<Unit> {
    val scope = CoroutineScope(Job())
    scope.launch {
        val result = async {
            println("Throwing exception from async")
            delay(100)
            println("抛异常")
            throw AssertionError("test")
        }
        delay(200)
        try {
            result.await()
        } catch (e: Throwable) {
            println("try catch 异常:$e")
        }
        println("代码结束")
    }.join()
}
```

运行结果：

![image-20220811152604911](https://raw.githubusercontent.com/meiSThub/BlogImage/master/2022image-20220811152604911.png)

从运行的结果也可以看出，async 子协程，确实是在 async 协程运行的时候，就立刻抛出了，而不是等到 await 方法才抛出。

总结参考：[四、总结](#四、总结)

协程的异常处理流程，以下图为例做个总结，**Job5** 处发生异常（此处指非CancellationException）。

![image-20220811141646099](https://raw.githubusercontent.com/meiSThub/BlogImage/master/2022image-20220811141646099.png)

1. Job5首先会把异常传递给Job2处理。Job2有两种选择，选择一是不处理该异常，将异常打回给Job5，Job5调用handleJobException方法。选择二是Job2选择处理该异常，那么异常就传递给Job2了，Job5再也没有机会处理异常。
2. Job2处理异常的逻辑同Job5，首先会把异常传递给Job0。Job0同样有两种选择，打回交由Job2处理，调用Job2的handleJobException方法或者由Job0处理。
3. 协程中根Job是不会处理异常的，它会将异常打回交由子Job处理。本例子中Job0会把异常交由Job2处理。
4. Job的handleJobException处理异常的逻辑是，首先判断协程的context是否设置过CoroutineExceptionHandler，如果有则交由CoroutineExceptionHandler处理异常。如果没设置过则会交由AndroidExceptionPreHandler处理。
5. async 作为根协程，可以通过 try catch 捕获异常，作为子协程与 launch 协程一致。

*有几个需要注意的点*

1. CancellationException传播给父Job，一定会被打回。换而言之，它不会影响父Job。
2. SupervisorJob和supervisorScope一样会把异常打回给子Job处理，它们都可以把异常掐死在内部，不往外传播。
3. coroutineScope和withContext可以把协程的异常rethrow，也就是可以在他们外层加try catch捕获。
4. supervisorScope 同样继承外部作用域的上下文，但其内部的取消操作是单向传播的，父协程向子协程传播，反过来则不然，这意味着子协程出了异常并不会影响父协程以及其他兄弟协程。它更适合一些独立不相干的任务，任何一个任务出问题，并不会影响其他任务的工作。

# 三、项目中如何使用协程

------

在现有项目中，网络请求都是通过 RxJava + OkHttp 完成，并通过接口回调的方式获取请求的结果，对于这样的老项目而言，该如何使用协程呢？可以借助如下两个方法来完成：

* suspendCoroutine
* suspendCancellableCoroutine

这两个方法就可以将回调的方式，转换成协程的方式。

Model 层有一个获取天气的方法：

```kotlin
fun getWeather(city:String,callback: OnHttpCallBack<String>) {
    MyHttp.postJson(url)
                  .param("city", city)
                  .execute(callBack)
}
```

接口：

```kotlin
interface HttpCallBack<T> {
    fun onSuccess(data: T)
    fun onFail(errorCode: String?, errorMsg: String?)
}
```

## 1、接口回调方式

在ViewModel中调用：

```kotlin
repository.getWeather(object :HttpCallBack<String>{
    override fun onSuccess(data: String) {
        textView.text = data //请求成功，刷新UI 
    }

    override fun onFail(errorCode: String?, errorMsg: String?) {
       Toast.makeText(this@MainActivity, errorMsg, Toast.LENGTH_SHORT).show()
    }
})
```



## 2、使用协程

使用协程的方式，把接口回调，改成同步代码。具体如下：

（1）修改model 层的方法：

```kotlin
suspend fun getWeather(city: String): String = suspendCoroutine { continuation: Continuation<String> ->
        MyHttp.postJson(url)
            .param("city", city)
            .execute(object : HttpCallBack<String> {// 异步执行请求
            override fun onSuccess(data: String) {
                // 通过 Continuation 对象，返回请求的接口
                continuation.resume(data)
            }

                override fun onFail(errorCode: String?, errorMsg: String?) {
                    // 通过Continuation对象，抛出异常
                    continuation.resumeWithException(ServerException(errorCode, errorMsg))
                }
            })
    }
```

（2）在ViewModel层使用：

```kotlin
viewModelScope.launch {
    val weather = try {
        repository.getWeather("深圳") // 获取天气
    } catch (e: Throwable) {
        null
    }
    textView.text = weather
}
```

借助 suspendCoroutine 方法，就把一个请求变成同步代码的方式。



## 3-3、suspendCoroutine 和 suspendCancellableCoroutine 的区别

* （1）使用 suspendCancellableCoroutine 和 suspendCoroutine 都可以将回调函数转换为协程
* （2）suspendCancellableCoroutine 返回一个 CancellableContinuation， 它可以用 resume、resumeWithException 来处理回调 和抛出 CancellationException 异常。它与 suspendCoroutine的唯一区别就是 suspendCancellableCoroutine 可以通过 cancel() 方法手动取消协程的执行，而 suspendCoroutine 没有该方法。

* （3）尽可能使用 suspendCancellableCoroutine 而不是 suspendCoroutine ，因为协程的取消是可控的

**举个例子**：使用网络请求数据时，如果请求时间过长，用户可以手动取消掉协程的执行。这时会抛出一个 CancellationException 异常，但是将该异常try{}catch{}捕获后就不会影响后续代码的执行。而使用 suspendCoroutine 只能干等着被 resume 或者 resumeWithException ，因为它没有该功能。

# 四、总结：

------



1. Job树异常的传递：

   当 Job 的 childCancelled 方法返回false 的时候，就需要当前Job自己处理异常。childCancelled 方法返回 false 的场景有：

   * （1）当前Job的父节点 是根节点
   * （2）当前Job的父节点是 SupervisorJob。

2. 异常的三道锁：
   * （1）try catch
   * （2）CoroutineExceptionHandler
   * （3）UncaughtExceptionHandler

3. 老项目使用协程
   * suspendCoroutine
   * suspendCancellableCoroutine

# 参考博客：

------

* [抽丝剥茧聊Kotlin协程之协程异常处理机制分析](https://juejin.cn/post/7049537608262615070)
* [抽丝剥茧聊Kotlin协程之聊聊Job和SupervisorJob的区别](https://juejin.cn/post/7046191497628090399)
* [抽丝剥茧聊Kotlin协程之Job初体验](https://juejin.cn/post/7042549383006519303)
* [kotlin协程async await的异常踩坑以及异常处理的正确姿势](https://blog.csdn.net/yuzhiqiang_1993/article/details/121049744)
* [kotlin 协程的异常处理](https://zhuanlan.zhihu.com/p/424591901)
* [「Kotlin篇」多方位处理协程的异常](https://juejin.cn/post/6973616939151130654)
* [史上最详Android版kotlin协程入门进阶实战(三)](https://juejin.cn/post/6954250061207306253)
* [官方：Android 上的 Kotlin 协程](https://developer.android.google.cn/kotlin/coroutines?hl=zh-cn)
* [官方：异常处理与监督](https://www.kotlincn.net/docs/reference/coroutines/exception-handling.html)